Workbook

Sheet Sheet1
A1: project | B1: api_level | C1: source | D1: yml_count
A2: yacguide | B2: 33 | C2: hardcoded | D2: 2
A3: exif-thumbnail-adder | B3: 33 | C3: hardcoded | D3: 1
A4: NewPipe | B4: 33 | C4: hardcoded | D4: 3
A5: ez-recipes-android | B5: 33 | C5: matrix | D5: 2
A6: NotePad | B6: 33 | C6: matrix | D6: 4
A7: kiwix-android | B7: 33 | C7: matrix | D7: 5

Sheet Sheet5
A1: project | B1: api_level | C1: source | D1: yml_count | E1: check
A2: ToxAndroidRefImpl | B2: 29 | C2: hardcoded | D2: 9 | E2: =VLOOKUP(A:A,Sheet6!A:A,1,FALSE) -> ToxAndroidRefImpl
A3: apps-android-wikipedia | B3: 29 | C3: hardcoded | D3: 4 | E3: =VLOOKUP(A:A,Sheet6!A:A,1,FALSE) -> apps-android-wikipedia
A4: audio-recorder | B4: 29 | C4: hardcoded | D4: 2 | E4: =VLOOKUP(A:A,Sheet6!A:A,1,FALSE) -> audio-recorder
A5: ci-matters | B5: 29 | C5: hardcoded | D5: 3 | E5: =VLOOKUP(A:A,Sheet6!A:A,1,FALSE) -> ci-matters
A6: RLAD | B6: 29 | C6: hardcoded | D6: 1 | E6: =VLOOKUP(A:A,Sheet6!A:A,1,FALSE) -> RLAD
A7: ObdGraphs | B7: 29 | C7: hardcoded | D7: 1 | E7: =VLOOKUP(A:A,Sheet6!A:A,1,FALSE) -> ObdGraphs
A8: photochat | B8: 29 | C8: hardcoded | D8: 4 | E8: =VLOOKUP(A:A,Sheet6!A:A,1,FALSE) -> photochat
A9: tasks | B9: 29 | C9: hardcoded | D9: 2 | E9: =VLOOKUP(A:A,Sheet6!A:A,1,FALSE) -> tasks
A10: swisscovid-app-android | B10: 29 | C10: hardcoded | D10: 4 | E10: =VLOOKUP(A:A,Sheet6!A:A,1,FALSE) -> swisscovid-app-android
A11: arduino-usb-terminal | B11: 29 | C11: hardcoded | D11: 2 | E11: =VLOOKUP(A:A,Sheet6!A:A,1,FALSE) -> arduino-usb-terminal
A12: ExpenseManager | B12: 29 | C12: hardcoded | D12: 1 | E12: =VLOOKUP(A:A,Sheet6!A:A,1,FALSE) -> ExpenseManager
A13: Palette-Compose | B13: 29 | C13: hardcoded | D13: 2 | E13: =VLOOKUP(A:A,Sheet6!A:A,1,FALSE) -> Palette-Compose
... A67: OneHotMinute-Compose | B67: 29 | C67: matrix | D67: 1 | E67: =VLOOKUP(A:A,Sheet6!A:A,1,FALSE) -> OneHotMinute-Compose

Sheet Sheet6
A1: project | B1: api_level | C1: source | D1: yml_count | E1: with Inst. Test
A2: ez-recipes-android | B2: 29 | C2: matrix | D2: 2 | E2: ez-recipes-android
A3: ToxAndroidRefImpl | B3: 29 | C3: hardcoded | D3: 9 | E3: ToxAndroidRefImpl
A4: apps-android-wikipedia | B4: 29 | C4: hardcoded | D4: 4 | E4: apps-android-wikipedia
A5: audio-recorder | B5: 29 | C5: hardcoded | D5: 2 | E5: audio-recorder
A6: ci-matters | B6: 29 | C6: hardcoded | D6: 3 | E6: ci-matters
A7: RLAD | B7: 29 | C7: hardcoded | D7: 1 | E7: RLAD
A8: ObdGraphs | B8: 29 | C8: hardcoded | D8: 1 | E8: ObdGraphs
A9: photochat | B9: 29 | C9: hardcoded | D9: 4 | E9: photochat
A10: compose-challenges | B10: 29 | C10: matrix | D10: 1 | E10: compose-challenges
A11: secure-storage-android | B11: 29 | C11: matrix | D11: 3 | E11: secure-storage-android
A12: exif-thumbnail-adder | B12: 29 | C12: matrix | D12: 1 | E12: exif-thumbnail-adder
A13: tasks | B13: 29 | C13: hardcoded | D13: 2 | E13: tasks
... A66: Transportr | B66: 29 | C66: matrix | D66: 1 | E66: Transportr

Sheet project_api_levels_detailed
A1: project | B1: api_level | C1: source | D1: yml_count | E1: with Inst. Test | M1: with Inst. Test | N1: (Multiple Items)
A2: ez-recipes-android | B2: 29 | C2: matrix | D2: 2 | E2: =VLOOKUP(A:A,'282 Projects'!A:B,1,FALSE) -> ez-recipes-android
A3: ez-recipes-android | B3: 33 | C3: matrix | D3: 2 | E3: =VLOOKUP(A:A,'282 Projects'!A:B,1,FALSE) -> ez-recipes-android | G3: Count of project | H3: Column Labels | M3: Row Labels | N3: Count of project | P3: API-Levels | Q3: Count of project (out of 282)
A4: ez-recipes-android | B4: 31 | C4: matrix | D4: 2 | E4: =VLOOKUP(A:A,'282 Projects'!A:B,1,FALSE) -> ez-recipes-android | G4: Row Labels | H4: hardcoded | I4: matrix | J4: Grand Total | M4: 29 | N4: 65 | P4: 29 | Q4: 65
A5: android | B5: 27 | C5: matrix | D5: 41 | E5: =VLOOKUP(A:A,'282 Projects'!A:B,1,FALSE) -> android | G5: 29 | H5: 27 | I5: 39 | J5: 66 | M5: 23 | N5: 24 | P5: 23 | Q5: 24
A6: android | B6: 31 | C6: matrix | D6: 41 | E6: =VLOOKUP(A:A,'282 Projects'!A:B,1,FALSE) -> android | G6: 23 | I6: 24 | J6: 24 | M6: 26 | N6: 23 | P6: 26 | Q6: 23
A7: RLAD | B7: 29 | C7: hardcoded | D7: 1 | E7: =VLOOKUP(A:A,'282 Projects'!A:B,1,FALSE) -> RLAD | G7: 26 | H7: 2 | I7: 21 | J7: 23 | M7: 31 | N7: 21 | P7: 31 | Q7: 21
A8: compose-challenges | B8: 26 | C8: matrix | D8: 1 | E8: =VLOOKUP(A:A,'282 Projects'!A:B,1,FALSE) -> compose-challenges | G8: 31 | H8: 10 | I8: 12 | J8: 22 | M8: 28 | N8: 18 | P8: 28 | Q8: 18
A9: compose-challenges | B9: 23 | C9: matrix | D9: 1 | E9: =VLOOKUP(A:A,'282 Projects'!A:B,1,FALSE) -> compose-challenges | G9: 28 | H9: 9 | I9: 9 | J9: 18 | M9: 30 | N9: 14 | P9: 30 | Q9: 14
A10: compose-challenges | B10: 29 | C10: matrix | D10: 1 | E10: =VLOOKUP(A:A,'282 Projects'!A:B,1,FALSE) -> compose-challenges | G10: 30 | H10: 6 | I10: 8 | J10: 14 | M10: 21 | N10: 13 | P10: 21 | Q10: 13
A11: secure-storage-android | B11: 29 | C11: matrix | D11: 3 | E11: =VLOOKUP(A:A,'282 Projects'!A:B,1,FALSE) -> secure-storage-android | G11: 21 | H11: 5 | I11: 8 | J11: 13 | M11: 33 | N11: 6 | P11: 33 | Q11: 6
A12: secure-storage-android | B12: 23 | C12: matrix | D12: 3 | E12: =VLOOKUP(A:A,'282 Projects'!A:B,1,FALSE) -> secure-storage-android | G12: 33 | H12: 3 | I12: 3 | J12: 6 | M12: 24 | N12: 4 | P12: 24 | Q12: 4
A13: secure-storage-android | B13: 22 | C13: matrix | D13: 3 | E13: =VLOOKUP(A:A,'282 Projects'!A:B,1,FALSE) -> secure-storage-android | G13: 24 | H13: 3 | I13: 1 | J13: 4 | M13: 22 | N13: 4 | P13: 22 | Q13: 4
A14: secure-storage-android | B14: 25 | C14: matrix | D14: 3 | E14: =VLOOKUP(A:A,'282 Projects'!A:B,1,FALSE) -> secure-storage-android | G14: 22 | H14: 2 | I14: 2 | J14: 4 | M14: 27 | N14: 4 | P14: 27 | Q14: 4
A15: secure-storage-android | B15: 21 | C15: matrix | D15: 3 | E15: =VLOOKUP(A:A,'282 Projects'!A:B,1,FALSE) -> secure-storage-android | G15: 27 | H15: 1 | I15: 3 | J15: 4 | M15: 19 | N15: 3 | P15: 19 | Q15: 3
A16: ExpenseManager | B16: 29 | C16: hardcoded | D16: 1 | E16: =VLOOKUP(A:A,'282 Projects'!A:B,1,FALSE) -> ExpenseManager | G16: 19 | H16: 1 | I16: 2 | J16: 3 | M16: 25 | N16: 3 | P16: 25 | Q16: 3
A17: Palette-Compose | B17: 29 | C17: hardcoded | D17: 2 | E17: =VLOOKUP(A:A,'282 Projects'!A:B,1,FALSE) -> Palette-Compose | G17: 25 | H17: 1 | I17: 2 | J17: 3 | M17: 32 | N17: 2 | P17: 32 | Q17: 2
A18: FastShopping | B18: 28 | C18: hardcoded | D18: 6 | E18: =VLOOKUP(A:A,'282 Projects'!A:B,1,FALSE) -> FastShopping | G18: 32 | H18: 2 | J18: 2 | M18: 16 | N18: 1 | P18: 16 | Q18: 1
A19: RickAndMorty | B19: 29 | C19: hardcoded | D19: 6 | E19: =VLOOKUP(A:A,'282 Projects'!A:B,1,FALSE) -> RickAndMorty | G19: 16 | I19: 1 | J19: 1 | M19: Grand Total | N19: 205 | P19: Grand Total | Q19: 205
A20: CoffeeDrinksWithJetpackCompose | B20: 31 | C20: hardcoded | D20: 2 | E20: =VLOOKUP(A:A,'282 Projects'!A:B,1,FALSE) -> CoffeeDrinksWithJetpackCompose | G20: Grand Total | H20: 72 | I20: 135 | J20: 207
A21: and-bible | B21: 31 | C21: hardcoded | D21: 7 | E21: =VLOOKUP(A:A,'282 Projects'!A:B,1,FALSE) -> and-bible
A22: trekarta | B22: 23 | C22: matrix | D22: 3 | E22: =VLOOKUP(A:A,'282 Projects'!A:B,1,FALSE) -> trekarta
A23: trekarta | B23: 29 | C23: matrix | D23: 3 | E23: =VLOOKUP(A:A,'282 Projects'!A:B,1,FALSE) -> trekarta
A24: Anki-Android | B24: 30 | C24: matrix | D24: 12 | E24: =VLOOKUP(A:A,'282 Projects'!A:B,1,FALSE) -> Anki-Android
A25: AntennaPod | B25: 30 | C25: hardcoded | D25: 2 | E25: =VLOOKUP(A:A,'282 Projects'!A:B,1,FALSE) -> AntennaPod | G25: API-LEVEL | H25: Grand Total
A26: EasyRecipe | B26: 28 | C26: hardcoded | D26: 3 | E26: =VLOOKUP(A:A,'282 Projects'!A:B,1,FALSE) -> EasyRecipe | G26: 29 | H26: 66
A27: weather-forecast-ID | B27: 29 | C27: hardcoded | D27: 3 | E27: =VLOOKUP(A:A,'282 Projects'!A:B,1,FALSE) -> weather-forecast-ID | G27: 23 | H27: 24
A28: Aegis | B28: 31 | C28: hardcoded | D28: 3 | E28: =VLOOKUP(A:A,'282 Projects'!A:B,1,FALSE) -> Aegis | G28: 26 | H28: 23
A29: mobile | B29: 31 | C29: hardcoded | D29: 9 | E29: =VLOOKUP(A:A,'282 Projects'!A:B,1,FALSE) -> mobile | G29: 31 | H29: 22
A30: icsx5 | B30: 31 | C30: matrix | D30: 4 | E30: =VLOOKUP(A:A,'282 Projects'!A:B,1,FALSE) -> icsx5 | G30: 28 | H30: 18
A31: learn-braille | B31: 29 | C31: hardcoded | D31: 1 | E31: =VLOOKUP(A:A,'282 Projects'!A:B,1,FALSE) -> learn-braille | G31: 30 | H31: 14
A32: sdp-project | B32: 24 | C32: hardcoded | D32: 1 | E32: =VLOOKUP(A:A,'282 Projects'!A:B,1,FALSE) -> sdp-project | G32: 21 | H32: 13
A33: Bookworm | B33: 29 | C33: hardcoded | D33: 2 | E33: =VLOOKUP(A:A,'282 Projects'!A:B,1,FALSE) -> Bookworm | G33: 33 | H33: 6
A34: Bark | B34: 26 | C34: matrix | D34: 1 | E34: =VLOOKUP(A:A,'282 Projects'!A:B,1,FALSE) -> Bark | G34: 24 | H34: 4
A35: Bark | B35: 23 | C35: matrix | D35: 1 | E35: =VLOOKUP(A:A,'282 Projects'!A:B,1,FALSE) -> Bark | G35: 22 | H35: 4
A36: Bark | B36: 29 | C36: matrix | D36: 1 | E36: =VLOOKUP(A:A,'282 Projects'!A:B,1,FALSE) -> Bark | G36: 27 | H36: 4
A37: curriculumvitae | B37: 26 | C37: matrix | D37: 3 | E37: =VLOOKUP(A:A,'282 Projects'!A:B,1,FALSE) -> curriculumvitae | G37: 19 | H37: 3
... A40: curriculumvitae | B40: 31 | C40: matrix | D40: 3 | E40: =VLOOKUP(A:A,'282 Projects'!A:B,1,FALSE) -> curriculumvitae | G40: 16 | H40: 1
A41: curriculumvitae | B41: 30 | C41: hardcoded | D41: 3 | E41: =VLOOKUP(A:A,'282 Projects'!A:B,1,FALSE) -> curriculumvitae | G41: Grand Total | H41: 207
A42: connectbot | B42: 28 | C42: hardcoded | D42: 4 | E42: =VLOOKUP(A:A,'282 Projects'!A:B,1,FALSE) -> connectbot
...

Sheet 282 Projects
A1: project | B1: test_types
A2: Detoxiom | B2: GitHub_gradle
A3: ez-recipes-android | B3: GitHub_emulator_full, GitHub_gradle
A4: android | B4: GitHub_emulator_full, GitHub_emulator_manual
A5: AcDisplay | B5: GitHub_emulator_manual, GitHub_gradle
A6: aw-android | B6: GitHub_emulator_manual
A7: RLAD | B7: GitHub_emulator_full, GitHub_gradle
A8: CovidCertificate-App-Android | B8: browserstack_test
A9: compose-challenges | B9: GitHub_emulator_full, GitHub_gradle
A10: secure-storage-android | B10: GitHub_emulator_full, GitHub_gradle
A11: ExpenseManager | B11: GitHub_emulator_full, GitHub_gradle
A12: Palette-Compose | B12: GitHub_emulator_full, GitHub_gradle
... A283: dialogue | B283: GitHub_emulator_full, GitHub_gradle
